Workbook

Sheet Léame
A1: GesLab · Inventario de laboratorios · Sede Carepa
A2: Versión 2 generada el 29/10/2026 a partir de los archivos originales (no se modificaron; siguen intactos en la carpeta Inventario).
A4: CÓMO DILIGENCIARLO (3 pasos)
A5: 1. Revisar: en Reactivos y Equipos, filtre la columna «Revisar» = Sí. Cada fila trae el motivo. Corrija el dato y cambie «Revisar» a No. Así queda constancia de lo verificado.
A6: 2. Registrar consumos: hoja Movimientos. Una fila por uso: fecha, ID del reactivo (lista desplegable), cantidad usada. «Existencia hoy» se recalcula sola.
A7: 3. Registrar roturas de vidriería: hoja Roturas, igual que Movimientos. Para ítems nuevos de vidriería, llene la hoja Vidriería (una fila por ítem).
A9: COLORES
A10: Encabezado azul oscuro = usted escribe. Encabezado gris = fórmula o dato fijo, no se digita. Fila amarilla = por revisar. Rojo = vencido, negativo o no disponible. Naranja = por vencer, repetido o con traslado pendiente.
A12: REGLAS APLICADAS AL UNIFICAR
A13: Unidades convertidas a g, mL o unidad (kg→g, L→mL, mg→g). La unidad original queda en la columna Origen cuando se cambió.
A14: Cantidades escritas como texto («300g», «3.5L») se separaron en número y unidad. Lo ambiguo quedó marcado en Revisar.
A15: Reactivos vencidos se cargaron igual y quedan marcados como VENCIDO; los que vencen en menos de 90 días, como Por vencer. No cuentan como disponibles hasta que usted lo decida.
... A23: Al terminar, avise para cargar estos libros a GesLab: la existencia de cada práctica se comparará automáticamente con lo solicitado.

Sheet Listas
A1: Unidad | B1: Estado físico | C1: Tipo | D1: Estado del equipo | E1: Condición | F1: Prestado o enviado a | G1: Sí/No | H1: Material | I1: Área | J1: Salón o laboratorio | K1: Clase de almacenamiento
A2: g | B2: Sólido | C2: Reactivo | D2: Operativo | E2: Buena | F2: Turbo | G2: Sí | H2: Vidrio | I2: Química | J2: 101 | K2: 10-10
A3: mL | B3: Líquido | C3: Solución o secundario | D3: En mantenimiento | E3: Regular | F3: Apartadó | G3: No | H3: Plástico | I3: Biología | J3: 102 | K3: 10-12
A4: unidad | B4: Gas | D4: Fuera de servicio | E4: Mala | F4: Carepa | H4: Porcelana | I4: Física | J4: 103 | K4: 10-13
D5: Baja | F5: Medellín (Centro de Instrumentación) | H5: Metal | I5: Otra | K5: 10-15
F6: Otra sede (indicar cuál) | H6: Otro | K6: 10-9
K7: 3
K8: 4.1
K9: 5.1
K10: 6.1
K11: 6.1B
K12: 8
K13: 8A
K14: 8B
K15: Calse8A
K16: Microbiológico

Sheet Reactivos
A1: ID | B1: Revisar | C1: Motivo de revisión | D1: Reactivo | E1: Fórmula | F1: CAS | G1: Estado físico | H1: Unidad | I1: Cantidad inicial | J1: Existencia (último conteo) | K1: Fecha del conteo | L1: Consumido desde el conteo | M1: Existencia hoy | N1: Vencimiento | O1: Estado vencimiento | P1: Lote | Q1: Marca | R1: Pureza / concentración | S1: Clase de almacenamiento | T1: Ubicación | U1: Cód. interno | V1: Recibió | W1: Tipo | X1: Base de la existencia | Y1: Observaciones | Z1: Origen (archivo · hoja · fila)
A2: REA-CAR-0001 | B2: No | D2: 1,10 Fenaltrolina Monihidratado | E2: C12H8N2 | F2: 5144-89-8 | G2: Sólido | H2: g | I2: 25 | J2: 4 | L2: =IF(D2="","",SUMIFS(Movimientos!$D$2:$D$2000,Movimientos!$B$2:$B$2000,A2)) -> 0 | M2: =IF(J2="","",J2-L2) -> 4 | O2: =IF(D2="","",IF(N2="","Sin fecha",IF(N2<TODAY(),"VENCIDO",IF(N2<TODAY()+90,"Por vencer","Vigente")))) -> Sin fecha | P2: K46484825 519 | Q2: Merck | R2: 100 | S2: 6.1 | V2: Carolina Galvis Lora | W2: Reactivo | X2: Cantidad total del inventario | Z2: Inventario_Reactivos_Carepa.xlsx · Reactivos · fila 2
A3: REA-CAR-0002 | B3: No | D3: 1-Naftol | E3: C10H8O | F3: 90-15-3 | G3: Sólido | H3: g | I3: 250 | J3: 240 | L3: =IF(D3="","",SUMIFS(Movimientos!$D$2:$D$2000,Movimientos!$B$2:$B$2000,A3)) -> 0 | M3: =IF(J3="","",J3-L3) -> 240 | N3: 45231 | O3: =IF(D3="","",IF(N3="","Sin fecha",IF(N3<TODAY(),"VENCIDO",IF(N3<TODAY()+90,"Por vencer","Vigente")))) -> VENCIDO | P3: 1251792 | Q3: Panreac | R3: 99 | S3: 6.1 | U3: IF012 | V3: Carolina Galvis Lora | W3: Reactivo | X3: Cantidad total del inventario | Z3: Inventario_Reactivos_Carepa.xlsx · Reactivos · fila 3
A4: REA-CAR-0003 | B4: No | D4: 1 - Propanol | E4: CH3CH(OH)CH2 | F4: 67-63-0 | G4: Líquido | H4: mL | I4: 0 | J4: 0 | L4: =IF(D4="","",SUMIFS(Movimientos!$D$2:$D$2000,Movimientos!$B$2:$B$2000,A4)) -> 0 | M4: =IF(J4="","",J4-L4) -> 0 | N4: 46234 | O4: =IF(D4="","",IF(N4="","Sin fecha",IF(N4<TODAY(),"VENCIDO",IF(N4<TODAY()+90,"Por vencer","Vigente")))) -> VENCIDO | P4: I1164334 136 | Q4: Merck | R4: 100 | S4: 3 | V4: Carolina Galvis Lora | W4: Reactivo | X4: Cantidad total del inventario | Z4: Inventario_Reactivos_Carepa.xlsx · Reactivos · fila 4
A5: REA-CAR-0004 | B5: No | D5: 2 - Propanol | E5: CH3CH(OH)CH3 | F5: 67-63-0 | G5: Líquido | H5: mL | I5: 5000 | J5: 5000 | L5: =IF(D5="","",SUMIFS(Movimientos!$D$2:$D$2000,Movimientos!$B$2:$B$2000,A5)) -> 0 | M5: =IF(J5="","",J5-L5) -> 5000 | N5: 46234 | O5: =IF(D5="","",IF(N5="","Sin fecha",IF(N5<TODAY(),"VENCIDO",IF(N5<TODAY()+90,"Por vencer","Vigente")))) -> VENCIDO | P5: l1164334136 | Q5: Merck | R5: 100 | S5: 3 | V5: Carolina Galvis Lora | W5: Reactivo | X5: Cantidad total del inventario | Z5: Inventario_Reactivos_Carepa.xlsx · Reactivos · fila 5
A6: REA-CAR-0005 | B6: No | D6: 2 - Propanol | E6: CH3CH(OH)CH3 | F6: 67-63-0 | G6: Líquido | H6: mL | I6: 5000 | J6: 4560 | L6: =IF(D6="","",SUMIFS(Movimientos!$D$2:$D$2000,Movimientos!$B$2:$B$2000,A6)) -> 0 | M6: =IF(J6="","",J6-L6) -> 4560 | N6: 44561 | O6: =IF(D6="","",IF(N6="","Sin fecha",IF(N6<TODAY(),"VENCIDO",IF(N6<TODAY()+90,"Por vencer","Vigente")))) -> VENCIDO | P6: K48600434 652 | Q6: Merck | R6: 100 | S6: 3 | V6: Carolina Galvis Lora | W6: Reactivo | X6: Cantidad total del inventario | Z6: Inventario_Reactivos_Carepa.xlsx · Reactivos · fila 6
A7: REA-CAR-0006 | B7: No | D7: 8 - Hidroxiquinoleina | E7: C9H7NO | F7: 148-24-3 | G7: Sólido | H7: g | I7: 250 | J7: 230 | L7: =IF(D7="","",SUMIFS(Movimientos!$D$2:$D$2000,Movimientos!$B$2:$B$2000,A7)) -> 0 | M7: =IF(J7="","",J7-L7) -> 230 | O7: =IF(D7="","",IF(N7="","Sin fecha",IF(N7<TODAY(),"VENCIDO",IF(N7<TODAY()+90,"Por vencer","Vigente")))) -> Sin fecha | P7: S7085061 530 | Q7: Merck | R7: 100 | S7: 10-13 | V7: Carolina Galvis Lora | W7: Reactivo | X7: Cantidad total del inventario | Z7: Inventario_Reactivos_Carepa.xlsx · Reactivos · fila 7
A8: REA-CAR-0007 | B8: No | D8: Aceite de inmersión para microscopía | E8: C14H12O2 | G8: Líquido | H8: mL | I8: 100 | J8: 50 | L8: =IF(D8="","",SUMIFS(Movimientos!$D$2:$D$2000,Movimientos!$B$2:$B$2000,A8)) -> 0 | M8: =IF(J8="","",J8-L8) -> 50 | N8: 43705 | O8: =IF(D8="","",IF(N8="","Sin fecha",IF(N8<TODAY(),"VENCIDO",IF(N8<TODAY()+90,"Por vencer","Vigente")))) -> VENCIDO | P8: V3H482273H | Q8: Carlo Erba | S8: 10-13 | U8: SR026 | V8: Carolina Galvis Lora | W8: Reactivo | X8: Cantidad total del inventario | Z8: Inventario_Reactivos_Carepa.xlsx · Reactivos · fila 8
A9: REA-CAR-0008 | B9: No | D9: Aceite de Parafia | G9: Líquido | H9: mL | I9: 125 | J9: 120 | L9: =IF(D9="","",SUMIFS(Movimientos!$D$2:$D$2000,Movimientos!$B$2:$B$2000,A9)) -> 0 | M9: =IF(J9="","",J9-L9) -> 120 | N9: 44865 | O9: =IF(D9="","",IF(N9="","Sin fecha",IF(N9<TODAY(),"VENCIDO",IF(N9<TODAY()+90,"Por vencer","Vigente")))) -> VENCIDO | P9: 1007214220 | Q9: BioMerieux | S9: 10-13 | V9: Carolina Galvis Lora | W9: Reactivo | X9: Cantidad total del inventario | Z9: Inventario_Reactivos_Carepa.xlsx · Reactivos · fila 9
A10: REA-CAR-0009 | B10: No | D10: Acetamida | E10: C2H5NO | F10: 022-00-4 | G10: Sólido | H10: g | I10: 100 | J10: 5 | L10: =IF(D10="","",SUMIFS(Movimientos!$D$2:$D$2000,Movimientos!$B$2:$B$2000,A10)) -> 0 | M10: =IF(J10="","",J10-L10) -> 5 | O10: =IF(D10="","",IF(N10="","Sin fecha",IF(N10<TODAY(),"VENCIDO",IF(N10<TODAY()+90,"Por vencer","Vigente")))) -> Sin fecha | P10: S6698643 446 | Q10: Merck | R10: 100 | S10: 6.1 | V10: Carolina Galvis Lora | W10: Reactivo | X10: Cantidad total del inventario | Z10: Inventario_Reactivos_Carepa.xlsx · Reactivos · fila 10
A11: REA-CAR-0010 | B11: No | D11: Acetanilida | E11: C8H9NO | F11: 103-84-4 | G11: Sólido | H11: g | I11: 500 | J11: 490 | L11: =IF(D11="","",SUMIFS(Movimientos!$D$2:$D$2000,Movimientos!$B$2:$B$2000,A11)) -> 0 | M11: =IF(J11="","",J11-L11) -> 490 | O11: =IF(D11="","",IF(N11="","Sin fecha",IF(N11<TODAY(),"VENCIDO",IF(N11<TODAY()+90,"Por vencer","Vigente")))) -> Sin fecha | P11: S73900544 828 | Q11: Merck | R11: 98 | S11: 6.1 | V11: Carolina Galvis Lora | W11: Reactivo | X11: Cantidad total del inventario | Z11: Inventario_Reactivos_Carepa.xlsx · Reactivos · fila 11
A12: REA-CAR-0011 | B12: No | D12: Acetato de etilo | E12: CH3COOC2H5 | F12: 141-78-6 | G12: Líquido | H12: mL | I12: 1000 | J12: 50 | L12: =IF(D12="","",SUMIFS(Movimientos!$D$2:$D$2000,Movimientos!$B$2:$B$2000,A12)) -> 0 | M12: =IF(J12="","",J12-L12) -> 50 | N12: 44530 | O12: =IF(D12="","",IF(N12="","Sin fecha",IF(N12<TODAY(),"VENCIDO",IF(N12<TODAY()+90,"Por vencer","Vigente")))) -> VENCIDO | P12: K50838323 848 | Q12: Merck | R12: 100 | S12: 3 | U12: IN016 | V12: Carolina Galvis Lora | W12: Reactivo | X12: Cantidad total del inventario | Z12: Inventario_Reactivos_Carepa.xlsx · Reactivos · fila 12
A13: REA-CAR-0012 | B13: No | D13: Acetato de plomo trihidratado | E13: (CH₃COO)₂Pb * 3 H₂O | F13: 6080-56-4 | G13: Sólido | H13: g | I13: 250 | J13: 250 | L13: =IF(D13="","",SUMIFS(Movimientos!$D$2:$D$2000,Movimientos!$B$2:$B$2000,A13)) -> 0 | M13: =IF(J13="","",J13-L13) -> 250 | O13: =IF(D13="","",IF(N13="","Sin fecha",IF(N13<TODAY(),"VENCIDO",IF(N13<TODAY()+90,"Por vencer","Vigente")))) -> Sin fecha | P13: S8189575 231 | Q13: Merck | R13: 100 | S13: 6.1 | U13: IF003 | V13: Carolina Galvis Lora | W13: Reactivo | X13: Cantidad total del inventario | Z13: Inventario_Reactivos_Carepa.xlsx · Reactivos · fila 13
A14: REA-CAR-0013 | B14: No | D14: Acetato de Sodio | E14: CH3COONa | F14: 127-09-3 | G14: Sólido | H14: g | I14: 1000 | J14: 400 | L14: =IF(D14="","",SUMIFS(Movimientos!$D$2:$D$2000,Movimientos!$B$2:$B$2000,A14)) -> 0 | M14: =IF(J14="","",J14-L14) -> 400 | O14: =IF(D14="","",IF(N14="","Sin fecha",IF(N14<TODAY(),"VENCIDO",IF(N14<TODAY()+90,"Por vencer","Vigente")))) -> Sin fecha | P14: AM1875868241 | Q14: Merck | R14: 99 | S14: 10-13 | V14: Carolina Galvis Lora | W14: Reactivo | X14: Cantidad total del inventario | Z14: Inventario_Reactivos_Carepa.xlsx · Reactivos · fila 14
A15: REA-CAR-0014 | B15: No | D15: Acetona | E15: CH3COCH3 | F15: 67-64-1 | G15: Líquido | H15: mL | I15: 2500 | J15: 2000 | L15: =IF(D15="","",SUMIFS(Movimientos!$D$2:$D$2000,Movimientos!$B$2:$B$2000,A15)) -> 0 | M15: =IF(J15="","",J15-L15) -> 2000 | N15: 45473 | O15: =IF(D15="","",IF(N15="","Sin fecha",IF(N15<TODAY(),"VENCIDO",IF(N15<TODAY()+90,"Por vencer","Vigente")))) -> VENCIDO | P15: K51483014 924 | Q15: Merck | R15: 100 | S15: 3 | U15: IN022 | V15: Carolina Galvis Lora | W15: Reactivo | X15: Cantidad total del inventario | Z15: Inventario_Reactivos_Carepa.xlsx · Reactivos · fila 15
A16: REA-CAR-0015 | B16: Sí | C16: CAS con formato no estándar: «609-994» | D16: Acido 3,5 Dinitrosalicilico 98% | E16: C7H4N2O7 | G16: Sólido | H16: g | I16: 100 | J16: 18 | L16: =IF(D16="","",SUMIFS(Movimientos!$D$2:$D$2000,Movimientos!$B$2:$B$2000,A16)) -> 0 | M16: =IF(J16="","",J16-L16) -> 18 | N16: 44866 | O16: =IF(D16="","",IF(N16="","Sin fecha",IF(N16<TODAY(),"VENCIDO",IF(N16<TODAY()+90,"Por vencer","Vigente")))) -> VENCIDO | P16: 985741 | Q16: Panreac | R16: 98 | S16: 8 | V16: Carolina Galvis Lora | W16: Reactivo | X16: Cantidad total del inventario | Y16: CAS/código original: 609-994 | Z16: Inventario_Reactivos_Carepa.xlsx · Reactivos · fila 16
A17: REA-CAR-0016 | B17: No | D17: Acido Acetico Glacial 100% | E17: CH3COOH | F17: 64-19-7 | G17: Líquido | H17: mL | I17: 1000 | J17: 1000 | L17: =IF(D17="","",SUMIFS(Movimientos!$D$2:$D$2000,Movimientos!$B$2:$B$2000,A17)) -> 0 | M17: =IF(J17="","",J17-L17) -> 1000 | N17: 44986 | O17: =IF(D17="","",IF(N17="","Sin fecha",IF(N17<TODAY(),"VENCIDO",IF(N17<TODAY()+90,"Por vencer","Vigente")))) -> VENCIDO | P17: 1976160 | Q17: Panreac | R17: 99.7 | S17: 8A | V17: Carolina Galvis Lora | W17: Reactivo | X17: Cantidad total del inventario | Z17: Inventario_Reactivos_Carepa.xlsx · Reactivos · fila 17
A18: REA-CAR-0017 | B18: No | D18: Acido Citrico monohidrato | E18: C6H8O7 * H2O | F18: 5949-29-1 | G18: Sólido | H18: g | I18: 500 | J18: 80 | L18: =IF(D18="","",SUMIFS(Movimientos!$D$2:$D$2000,Movimientos!$B$2:$B$2000,A18)) -> 0 | M18: =IF(J18="","",J18-L18) -> 80 | O18: =IF(D18="","",IF(N18="","Sin fecha",IF(N18<TODAY(),"VENCIDO",IF(N18<TODAY()+90,"Por vencer","Vigente")))) -> Sin fecha | P18: K48283044 711 | Q18: Merck | R18: 100 | S18: 10-13 | V18: Carolina Galvis Lora | W18: Reactivo | X18: Cantidad total del inventario | Z18: Inventario_Reactivos_Carepa.xlsx · Reactivos · fila 18
A19: REA-CAR-0018 | B19: No | D19: Acido ascorbico | E19: C6H8O6 | F19: 50-81-7 | G19: Sólido | H19: g | I19: 250 | J19: 220 | L19: =IF(D19="","",SUMIFS(Movimientos!$D$2:$D$2000,Movimientos!$B$2:$B$2000,A19)) -> 0 | M19: =IF(J19="","",J19-L19) -> 220 | O19: =IF(D19="","",IF(N19="","Sin fecha",IF(N19<TODAY(),"VENCIDO",IF(N19<TODAY()+90,"Por vencer","Vigente")))) -> Sin fecha | P19: 5Y011101 | Q19: Panreac | R19: 99 | S19: 10-13 | V19: Carolina Galvis Lora | W19: Reactivo | X19: Cantidad total del inventario | Z19: Inventario_Reactivos_Carepa.xlsx · Reactivos · fila 19
A20: REA-CAR-0019 | B20: No | D20: Ácido clorhídrico | E20: HCl | F20: 7647-01-0 | G20: Líquido | H20: mL | I20: 2500 | J20: 200 | L20: =IF(D20="","",SUMIFS(Movimientos!$D$2:$D$2000,Movimientos!$B$2:$B$2000,A20)) -> 0 | M20: =IF(J20="","",J20-L20) -> 200 | N20: 43898 | O20: =IF(D20="","",IF(N20="","Sin fecha",IF(N20<TODAY(),"VENCIDO",IF(N20<TODAY()+90,"Por vencer","Vigente")))) -> VENCIDO | P20: K0680 | Q20: Honeywell | R20: 37 | S20: 8 | U20: CO008 | V20: Carolina Galvis Lora | W20: Reactivo | X20: Cantidad total del inventario | Z20: Inventario_Reactivos_Carepa.xlsx · Reactivos · fila 20
A21: REA-CAR-0020 | B21: No | D21: Ácido Cromotrópico, sal disódica dihidratado | E21: C10H10Na2O10S2 | F21: 5808-22-0 | G21: Sólido | H21: g | I21: 25 | J21: 10 | L21: =IF(D21="","",SUMIFS(Movimientos!$D$2:$D$2000,Movimientos!$B$2:$B$2000,A21)) -> 0 | M21: =IF(J21="","",J21-L21) -> 10 | O21: =IF(D21="","",IF(N21="","Sin fecha",IF(N21<TODAY(),"VENCIDO",IF(N21<TODAY()+90,"Por vencer","Vigente")))) -> Sin fecha | P21: L013052198 424 | Q21: Merck | R21: 98,1 | S21: 10-13 | V21: Carolina Galvis Lora | W21: Reactivo | X21: Cantidad total del inventario | Z21: Inventario_Reactivos_Carepa.xlsx · Reactivos · fila 21
A22: REA-CAR-0021 | B22: No | D22: Ácido Cromotrópico, sal disódica dihidratado | E22: C10H10Na2O10S2 | F22: 5808-22-0 | G22: Sólido | H22: g | I22: 25 | J22: 15 | L22: =IF(D22="","",SUMIFS(Movimientos!$D$2:$D$2000,Movimientos!$B$2:$B$2000,A22)) -> 0 | M22: =IF(J22="","",J22-L22) -> 15 | O22: =IF(D22="","",IF(N22="","Sin fecha",IF(N22<TODAY(),"VENCIDO",IF(N22<TODAY()+90,"Por vencer","Vigente")))) -> Sin fecha | P22: L013052198 336 | Q22: Merck | R22: 98,1 | S22: 10-13 | U22: SR013 | V22: Carolina Galvis Lora | W22: Reactivo | X22: Cantidad total del inventario | Z22: Inventario_Reactivos_Carepa.xlsx · Reactivos · fila 22
A23: REA-CAR-0022 | B23: No | D23: Acido Glioxilico | E23: C2H2O3*H2O | F23: 7732-18-5 | G23: Líquido | H23: mL | I23: 250 | J23: 120 | L23: =IF(D23="","",SUMIFS(Movimientos!$D$2:$D$2000,Movimientos!$B$2:$B$2000,A23)) -> 0 | M23: =IF(J23="","",J23-L23) -> 120 | O23: =IF(D23="","",IF(N23="","Sin fecha",IF(N23<TODAY(),"VENCIDO",IF(N23<TODAY()+90,"Por vencer","Vigente")))) -> Sin fecha | P23: S6734084 401 | Q23: Merck | R23: 50 | S23: 8 | V23: Carolina Galvis Lora | W23: Reactivo | X23: Cantidad total del inventario | Z23: Inventario_Reactivos_Carepa.xlsx · Reactivos · fila 23
A24: REA-CAR-0023 | B24: No | D24: Ácido nítrico | E24: HNO3 | F24: 7697-37-2 | G24: Líquido | H24: mL | I24: 5000 | J24: 3000 | L24: =IF(D24="","",SUMIFS(Movimientos!$D$2:$D$2000,Movimientos!$B$2:$B$2000,A24)) -> 0 | M24: =IF(J24="","",J24-L24) -> 3000 | N24: 43616 | O24: =IF(D24="","",IF(N24="","Sin fecha",IF(N24<TODAY(),"VENCIDO",IF(N24<TODAY()+90,"Por vencer","Vigente")))) -> VENCIDO | P24: K47933056 624 | Q24: Merck | R24: 65 | S24: 5.1 | U24: IN019 | V24: Carolina Galvis Lora | W24: Reactivo | X24: Cantidad total del inventario | Z24: Inventario_Reactivos_Carepa.xlsx · Reactivos · fila 24
A25: REA-CAR-0024 | B25: No | D25: Acido Orto-fosforico | E25: H3PO4 | F25: 7664-38-2 | G25: Líquido | H25: mL | I25: 1000 | J25: 700 | L25: =IF(D25="","",SUMIFS(Movimientos!$D$2:$D$2000,Movimientos!$B$2:$B$2000,A25)) -> 0 | M25: =IF(J25="","",J25-L25) -> 700 | N25: 44012 | O25: =IF(D25="","",IF(N25="","Sin fecha",IF(N25<TODAY(),"VENCIDO",IF(N25<TODAY()+90,"Por vencer","Vigente")))) -> VENCIDO | P25: K46816373 526 | Q25: Merck | R25: 85 | S25: 8B | V25: Carolina Galvis Lora | W25: Reactivo | X25: Cantidad total del inventario | Z25: Inventario_Reactivos_Carepa.xlsx · Reactivos · fila 25
A26: REA-CAR-0025 | B26: No | D26: Acido Salicilico | E26: C7H6O3 | F26: 69-72-7 | G26: Sólido | H26: g | I26: 100 | J26: 45 | L26: =IF(D26="","",SUMIFS(Movimientos!$D$2:$D$2000,Movimientos!$B$2:$B$2000,A26)) -> 0 | M26: =IF(J26="","",J26-L26) -> 45 | O26: =IF(D26="","",IF(N26="","Sin fecha",IF(N26<TODAY(),"VENCIDO",IF(N26<TODAY()+90,"Por vencer","Vigente")))) -> Sin fecha | P26: S6059431 231 | Q26: Merck | R26: 100 | S26: 8 | V26: Carolina Galvis Lora | W26: Reactivo | X26: Cantidad total del inventario | Z26: Inventario_Reactivos_Carepa.xlsx · Reactivos · fila 26
A27: REA-CAR-0026 | B27: No | D27: Ácido sulfúrico | E27: H2SO4 | F27: 7664-93-9 | G27: Líquido | H27: mL | I27: 2500 | J27: 2000 | L27: =IF(D27="","",SUMIFS(Movimientos!$D$2:$D$2000,Movimientos!$B$2:$B$2000,A27)) -> 0 | M27: =IF(J27="","",J27-L27) -> 2000 | N27: 46112 | O27: =IF(D27="","",IF(N27="","Sin fecha",IF(N27<TODAY(),"VENCIDO",IF(N27<TODAY()+90,"Por vencer","Vigente")))) -> VENCIDO | P27: K53264431 114 | Q27: Merck | R27: 95-97 | S27: 8A | U27: CO007 | V27: Carolina Galvis Lora | W27: Reactivo | X27: Cantidad total del inventario | Z27: Inventario_Reactivos_Carepa.xlsx · Reactivos · fila 27
A28: REA-CAR-0027 | B28: No | D28: Acido propionico | E28: C3H6O2 | F28: 79-09-4 | G28: Líquido | H28: mL | I28: 500 | J28: 480 | L28: =IF(D28="","",SUMIFS(Movimientos!$D$2:$D$2000,Movimientos!$B$2:$B$2000,A28)) -> 0 | M28: =IF(J28="","",J28-L28) -> 480 | O28: =IF(D28="","",IF(N28="","Sin fecha",IF(N28<TODAY(),"VENCIDO",IF(N28<TODAY()+90,"Por vencer","Vigente")))) -> Sin fecha | P28: S7746005 935 | Q28: Merck | R28: 99 | S28: Calse8A | V28: Carolina Galvis Lora | W28: Reactivo | X28: Cantidad total del inventario | Z28: Inventario_Reactivos_Carepa.xlsx · Reactivos · fila 28
A29: REA-CAR-0028 | B29: No | D29: Acido Tricloroacetico | E29: CCl3COOH | F29: 004-00-7 | G29: Sólido | H29: g | I29: 100 | J29: 1 | L29: =IF(D29="","",SUMIFS(Movimientos!$D$2:$D$2000,Movimientos!$B$2:$B$2000,A29)) -> 0 | M29: =IF(J29="","",J29-L29) -> 1 | O29: =IF(D29="","",IF(N29="","Sin fecha",IF(N29<TODAY(),"VENCIDO",IF(N29<TODAY()+90,"Por vencer","Vigente")))) -> Sin fecha | P29: K46702007 611 | Q29: Merck | R29: 100 | S29: 8B | V29: Carolina Galvis Lora | W29: Reactivo | X29: Cantidad total del inventario | Z29: Inventario_Reactivos_Carepa.xlsx · Reactivos · fila 29
A30: REA-CAR-0029 | B30: No | D30: Agar Agar | F30: 9002-18-0 | G30: Sólido | H30: g | I30: 1000 | J30: 1000 | L30: =IF(D30="","",SUMIFS(Movimientos!$D$2:$D$2000,Movimientos!$B$2:$B$2000,A30)) -> 0 | M30: =IF(J30="","",J30-L30) -> 1000 | N30: 46046 | O30: =IF(D30="","",IF(N30="","Sin fecha",IF(N30<TODAY(),"VENCIDO",IF(N30<TODAY()+90,"Por vencer","Vigente")))) -> VENCIDO | P30: VM1022714 219 | Q30: Merck | R30: 100 | S30: Microbiológico | V30: Carolina Galvis Lora | W30: Reactivo | X30: Cantidad total del inventario | Z30: Inventario_Reactivos_Carepa.xlsx · Reactivos · fila 30
A31: REA-CAR-0030 | B31: No | D31: Agar Cetrimide | G31: Sólido | H31: g | I31: 500 | J31: 450 | L31: =IF(D31="","",SUMIFS(Movimientos!$D$2:$D$2000,Movimientos!$B$2:$B$2000,A31)) -> 0 | M31: =IF(J31="","",J31-L31) -> 450 | N31: 44991 | O31: =IF(D31="","",IF(N31="","Sin fecha",IF(N31<TODAY(),"VENCIDO",IF(N31<TODAY()+90,"Por vencer","Vigente")))) -> VENCIDO | P31: VM817784 813 | Q31: Merck | R31: 100 | S31: Microbiológico | V31: Carolina Galvis Lora | W31: Reactivo | X31: Cantidad total del inventario | Z31: Inventario_Reactivos_Carepa.xlsx · Reactivos · fila 31
A32: REA-CAR-0031 | B32: No | D32: Agar Citrato de SIMMONS | G32: Sólido | H32: g | I32: 500 | J32: 250 | L32: =IF(D32="","",SUMIFS(Movimientos!$D$2:$D$2000,Movimientos!$B$2:$B$2000,A32)) -> 0 | M32: =IF(J32="","",J32-L32) -> 250 | N32: 45011 | O32: =IF(D32="","",IF(N32="","Sin fecha",IF(N32<TODAY(),"VENCIDO",IF(N32<TODAY()+90,"Por vencer","Vigente")))) -> VENCIDO | P32: VM831801 815 | Q32: Merck | R32: 100 | S32: Microbiológico | V32: Carolina Galvis Lora | W32: Reactivo | X32: Cantidad total del inventario | Z32: Inventario_Reactivos_Carepa.xlsx · Reactivos · fila 32
A33: REA-CAR-0032 | B33: No | D33: Agar EMB | G33: Sólido | H33: g | I33: 1000 | J33: 900 | L33: =IF(D33="","",SUMIFS(Movimientos!$D$2:$D$2000,Movimientos!$B$2:$B$2000,A33)) -> 0 | M33: =IF(J33="","",J33-L33) -> 900 | N33: 44797 | O33: =IF(D33="","",IF(N33="","Sin fecha",IF(N33<TODAY(),"VENCIDO",IF(N33<TODAY()+90,"Por vencer","Vigente")))) -> VENCIDO | P33: VM802442 738 | Q33: Merck | R33: 100 | S33: Microbiológico | V33: Carolina Galvis Lora | W33: Reactivo | X33: Cantidad total del inventario | Z33: Inventario_Reactivos_Carepa.xlsx · Reactivos · fila 33
A34: REA-CAR-0033 | B34: No | D34: Agar EMB | G34: Sólido | H34: g | I34: 500 | J34: 450 | L34: =IF(D34="","",SUMIFS(Movimientos!$D$2:$D$2000,Movimientos!$B$2:$B$2000,A34)) -> 0 | M34: =IF(J34="","",J34-L34) -> 450 | N34: 44671 | O34: =IF(D34="","",IF(N34="","Sin fecha",IF(N34<TODAY(),"VENCIDO",IF(N34<TODAY()+90,"Por vencer","Vigente")))) -> VENCIDO | P34: VM869847 912 | Q34: Merck | R34: 100 | S34: Microbiológico | V34: Carolina Galvis Lora | W34: Reactivo | X34: Cantidad total del inventario | Z34: Inventario_Reactivos_Carepa.xlsx · Reactivos · fila 34
A35: REA-CAR-0034 | B35: No | D35: Agar Endo | G35: Sólido | H35: g | I35: 500 | J35: 480 | L35: =IF(D35="","",SUMIFS(Movimientos!$D$2:$D$2000,Movimientos!$B$2:$B$2000,A35)) -> 0 | M35: =IF(J35="","",J35-L35) -> 480 | N35: 44839 | O35: =IF(D35="","",IF(N35="","Sin fecha",IF(N35<TODAY(),"VENCIDO",IF(N35<TODAY()+90,"Por vencer","Vigente")))) -> VENCIDO | P35: VM806344 743 | Q35: Merck | R35: 100 | S35: Microbiológico | V35: Carolina Galvis Lora | W35: Reactivo | X35: Cantidad total del inventario | Z35: Inventario_Reactivos_Carepa.xlsx · Reactivos · fila 35
A36: REA-CAR-0035 | B36: No | D36: Agar Glucosa 4% SABOURAUD | G36: Sólido | H36: g | I36: 500 | J36: 500 | L36: =IF(D36="","",SUMIFS(Movimientos!$D$2:$D$2000,Movimientos!$B$2:$B$2000,A36)) -> 0 | M36: =IF(J36="","",J36-L36) -> 500 | N36: 45900 | O36: =IF(D36="","",IF(N36="","Sin fecha",IF(N36<TODAY(),"VENCIDO",IF(N36<TODAY()+90,"Por vencer","Vigente")))) -> VENCIDO | P36: VM942138038 | Q36: Merck | R36: 100 | S36: Microbiológico | V36: Carolina Galvis Lora | W36: Reactivo | X36: Cantidad total del inventario | Z36: Inventario_Reactivos_Carepa.xlsx · Reactivos · fila 36
A37: REA-CAR-0036 | B37: No | D37: Agar Lisina - Hierro | G37: Sólido | H37: g | I37: 500 | J37: 480 | L37: =IF(D37="","",SUMIFS(Movimientos!$D$2:$D$2000,Movimientos!$B$2:$B$2000,A37)) -> 0 | M37: =IF(J37="","",J37-L37) -> 480 | N37: 44671 | O37: =IF(D37="","",IF(N37="","Sin fecha",IF(N37<TODAY(),"VENCIDO",IF(N37<TODAY()+90,"Por vencer","Vigente")))) -> VENCIDO | P37: VM784440 719 | Q37: Merck | R37: 100 | S37: Microbiológico | V37: Carolina Galvis Lora | W37: Reactivo | X37: Cantidad total del inventario | Z37: Inventario_Reactivos_Carepa.xlsx · Reactivos · fila 37
A38: REA-CAR-0037 | B38: No | D38: Agar Macconkey | G38: Sólido | H38: g | I38: 500 | J38: 450 | L38: =IF(D38="","",SUMIFS(Movimientos!$D$2:$D$2000,Movimientos!$B$2:$B$2000,A38)) -> 0 | M38: =IF(J38="","",J38-L38) -> 450 | O38: =IF(D38="","",IF(N38="","Sin fecha",IF(N38<TODAY(),"VENCIDO",IF(N38<TODAY()+90,"Por vencer","Vigente")))) -> Sin fecha | P38: VM732265614 | Q38: Merck | R38: 100 | S38: Microbiológico | V38: Carolina Galvis Lora | W38: Reactivo | X38: Cantidad total del inventario | Z38: Inventario_Reactivos_Carepa.xlsx · Reactivos · fila 38
A39: REA-CAR-0038 | B39: No | D39: Agar Macconkey | G39: Sólido | H39: g | I39: 500 | J39: 480 | L39: =IF(D39="","",SUMIFS(Movimientos!$D$2:$D$2000,Movimientos!$B$2:$B$2000,A39)) -> 0 | M39: =IF(J39="","",J39-L39) -> 480 | N39: 44613 | O39: =IF(D39="","",IF(N39="","Sin fecha",IF(N39<TODAY(),"VENCIDO",IF(N39<TODAY()+90,"Por vencer","Vigente")))) -> VENCIDO | P39: VM775965 712 | Q39: Merck | R39: 100 | S39: Microbiológico | V39: Carolina Galvis Lora | W39: Reactivo | X39: Cantidad total del inventario | Z39: Inventario_Reactivos_Carepa.xlsx · Reactivos · fila 39
A40: REA-CAR-0039 | B40: No | D40: Agar Nutritivo | G40: Sólido | H40: g | I40: 500 | J40: 250 | L40: =IF(D40="","",SUMIFS(Movimientos!$D$2:$D$2000,Movimientos!$B$2:$B$2000,A40)) -> 0 | M40: =IF(J40="","",J40-L40) -> 250 | N40: 44535 | O40: =IF(D40="","",IF(N40="","Sin fecha",IF(N40<TODAY(),"VENCIDO",IF(N40<TODAY()+90,"Por vencer","Vigente")))) -> VENCIDO | P40: VM769981 702 | Q40: Merck | R40: 100 | S40: Microbiológico | V40: Carolina Galvis Lora | W40: Reactivo | X40: Cantidad total del inventario | Z40: Inventario_Reactivos_Carepa.xlsx · Reactivos · fila 40
...

Sheet Movimientos
A1: Fecha | B1: ID reactivo | C1: Reactivo | D1: Cantidad usada | E1: Unidad | F1: Sesión / práctica | G1: Registró (técnico) | H1: Observación
C2: =IF(B2="","",IFERROR(INDEX(Reactivos!$D$2:$D$435,MATCH(B2,Reactivos!$A$2:$A$435,0)),"ID no existe")) | E2: =IF(B2="","",IFERROR(INDEX(Reactivos!$H$2:$H$435,MATCH(B2,Reactivos!$A$2:$A$435,0)),""))
C3: =IF(B3="","",IFERROR(INDEX(Reactivos!$D$2:$D$435,MATCH(B3,Reactivos!$A$2:$A$435,0)),"ID no existe")) | E3: =IF(B3="","",IFERROR(INDEX(Reactivos!$H$2:$H$435,MATCH(B3,Reactivos!$A$2:$A$435,0)),""))
C4: =IF(B4="","",IFERROR(INDEX(Reactivos!$D$2:$D$435,MATCH(B4,Reactivos!$A$2:$A$435,0)),"ID no existe")) | E4: =IF(B4="","",IFERROR(INDEX(Reactivos!$H$2:$H$435,MATCH(B4,Reactivos!$A$2:$A$435,0)),""))
C5: =IF(B5="","",IFERROR(INDEX(Reactivos!$D$2:$D$435,MATCH(B5,Reactivos!$A$2:$A$435,0)),"ID no existe")) | E5: =IF(B5="","",IFERROR(INDEX(Reactivos!$H$2:$H$435,MATCH(B5,Reactivos!$A$2:$A$435,0)),""))
C6: =IF(B6="","",IFERROR(INDEX(Reactivos!$D$2:$D$435,MATCH(B6,Reactivos!$A$2:$A$435,0)),"ID no existe")) | E6: =IF(B6="","",IFERROR(INDEX(Reactivos!$H$2:$H$435,MATCH(B6,Reactivos!$A$2:$A$435,0)),""))
C7: =IF(B7="","",IFERROR(INDEX(Reactivos!$D$2:$D$435,MATCH(B7,Reactivos!$A$2:$A$435,0)),"ID no existe")) | E7: =IF(B7="","",IFERROR(INDEX(Reactivos!$H$2:$H$435,MATCH(B7,Reactivos!$A$2:$A$435,0)),""))
C8: =IF(B8="","",IFERROR(INDEX(Reactivos!$D$2:$D$435,MATCH(B8,Reactivos!$A$2:$A$435,0)),"ID no existe")) | E8: =IF(B8="","",IFERROR(INDEX(Reactivos!$H$2:$H$435,MATCH(B8,Reactivos!$A$2:$A$435,0)),""))
C9: =IF(B9="","",IFERROR(INDEX(Reactivos!$D$2:$D$435,MATCH(B9,Reactivos!$A$2:$A$435,0)),"ID no existe")) | E9: =IF(B9="","",IFERROR(INDEX(Reactivos!$H$2:$H$435,MATCH(B9,Reactivos!$A$2:$A$435,0)),""))
C10: =IF(B10="","",IFERROR(INDEX(Reactivos!$D$2:$D$435,MATCH(B10,Reactivos!$A$2:$A$435,0)),"ID no existe")) | E10: =IF(B10="","",IFERROR(INDEX(Reactivos!$H$2:$H$435,MATCH(B10,Reactivos!$A$2:$A$435,0)),""))
C11: =IF(B11="","",IFERROR(INDEX(Reactivos!$D$2:$D$435,MATCH(B11,Reactivos!$A$2:$A$435,0)),"ID no existe")) | E11: =IF(B11="","",IFERROR(INDEX(Reactivos!$H$2:$H$435,MATCH(B11,Reactivos!$A$2:$A$435,0)),""))
C12: =IF(B12="","",IFERROR(INDEX(Reactivos!$D$2:$D$435,MATCH(B12,Reactivos!$A$2:$A$435,0)),"ID no existe")) | E12: =IF(B12="","",IFERROR(INDEX(Reactivos!$H$2:$H$435,MATCH(B12,Reactivos!$A$2:$A$435,0)),""))
C13: =IF(B13="","",IFERROR(INDEX(Reactivos!$D$2:$D$435,MATCH(B13,Reactivos!$A$2:$A$435,0)),"ID no existe")) | E13: =IF(B13="","",IFERROR(INDEX(Reactivos!$H$2:$H$435,MATCH(B13,Reactivos!$A$2:$A$435,0)),""))
... C2001: =IF(B2001="","",IFERROR(INDEX(Reactivos!$D$2:$D$435,MATCH(B2001,Reactivos!$A$2:$A$435,0)),"ID no existe")) | E2001: =IF(B2001="","",IFERROR(INDEX(Reactivos!$H$2:$H$435,MATCH(B2001,Reactivos!$A$2:$A$435,0)),""))

Sheet Equipos
A1: ID | B1: Revisar | C1: Motivo de revisión | D1: Equipo | E1: Marca | F1: Modelo | G1: Serie | H1: Cód. activo | I1: N° inventario | J1: Salón o laboratorio | K1: Área | L1: Cantidad | M1: Estado | N1: Condición | O1: Prestado o enviado a | P1: Disponibilidad para prácticas | Q1: Responsable | R1: Fecha del inventario | S1: Observaciones | T1: Origen (archivo · hoja · fila)
A2: EQP-CAR-0001 | B2: No | D2: ESTERIOSCOPIO | E2: OPTIKA | F2: SZM-2 | G2: 390835 | H2: 027797 | I2: 151909 | J2: 101 | L2: 1 | M2: Operativo | N2: Buena | P2: =IF(D2="","",IF(M2="Baja","No: dado de baja",IF(M2="Fuera de servicio","No: fuera de servicio",IF(M2="En mantenimiento","No: en mantenimiento",IF(O2<>"","Sí, pero está en "&O2&": hacer el traslado a Carepa","Sí"))))) -> Sí | T2: Inventario_Equipos_Carepa.xlsx · Carepa · fila 2
A3: EQP-CAR-0002 | B3: No | D3: ESTERIOSCOPIO | E3: OPTIKA | F3: SZM-2 | G3: 390839 | H3: 027798 | I3: 151910 | J3: 101 | L3: 1 | M3: Operativo | N3: Buena | P3: =IF(D3="","",IF(M3="Baja","No: dado de baja",IF(M3="Fuera de servicio","No: fuera de servicio",IF(M3="En mantenimiento","No: en mantenimiento",IF(O3<>"","Sí, pero está en "&O3&": hacer el traslado a Carepa","Sí"))))) -> Sí | T3: Inventario_Equipos_Carepa.xlsx · Carepa · fila 3
A4: EQP-CAR-0003 | B4: No | D4: ESTERIOSCOPIO | E4: OPTIKA | F4: SZM-2 | G4: 390834 | H4: 027800 | I4: 151912 | J4: 101 | L4: 1 | M4: Operativo | N4: Buena | P4: =IF(D4="","",IF(M4="Baja","No: dado de baja",IF(M4="Fuera de servicio","No: fuera de servicio",IF(M4="En mantenimiento","No: en mantenimiento",IF(O4<>"","Sí, pero está en "&O4&": hacer el traslado a Carepa","Sí"))))) -> Sí | T4: Inventario_Equipos_Carepa.xlsx · Carepa · fila 4
A5: EQP-CAR-0004 | B5: No | D5: ESTERIOSCOPIO | E5: OPTIKA | F5: SZM-2 | G5: 390847 | H5: 027801 | I5: 151913 | J5: 101 | L5: 1 | M5: Operativo | N5: Buena | P5: =IF(D5="","",IF(M5="Baja","No: dado de baja",IF(M5="Fuera de servicio","No: fuera de servicio",IF(M5="En mantenimiento","No: en mantenimiento",IF(O5<>"","Sí, pero está en "&O5&": hacer el traslado a Carepa","Sí"))))) -> Sí | T5: Inventario_Equipos_Carepa.xlsx · Carepa · fila 5
A6: EQP-CAR-0005 | B6: No | D6: ESTERIOSCOPIO | E6: OPTIKA | F6: SZM-2 | G6: 390841 | H6: 027802 | I6: 151914 | J6: 101 | L6: 1 | M6: Operativo | N6: Buena | P6: =IF(D6="","",IF(M6="Baja","No: dado de baja",IF(M6="Fuera de servicio","No: fuera de servicio",IF(M6="En mantenimiento","No: en mantenimiento",IF(O6<>"","Sí, pero está en "&O6&": hacer el traslado a Carepa","Sí"))))) -> Sí | T6: Inventario_Equipos_Carepa.xlsx · Carepa · fila 6
A7: EQP-CAR-0006 | B7: No | D7: ESTERIOSCOPIO | E7: OPTIKA | F7: SZM-2 | G7: 390836 | H7: 027803 | I7: 151915 | J7: 101 | L7: 1 | M7: Operativo | N7: Buena | P7: =IF(D7="","",IF(M7="Baja","No: dado de baja",IF(M7="Fuera de servicio","No: fuera de servicio",IF(M7="En mantenimiento","No: en mantenimiento",IF(O7<>"","Sí, pero está en "&O7&": hacer el traslado a Carepa","Sí"))))) -> Sí | T7: Inventario_Equipos_Carepa.xlsx · Carepa · fila 7
A8: EQP-CAR-0007 | B8: No | D8: ESTERIOSCOPIO | E8: OPTIKA | F8: SZM-2 | G8: 390833 | H8: 027804 | I8: 151916 | J8: 101 | L8: 1 | M8: Operativo | N8: Buena | P8: =IF(D8="","",IF(M8="Baja","No: dado de baja",IF(M8="Fuera de servicio","No: fuera de servicio",IF(M8="En mantenimiento","No: en mantenimiento",IF(O8<>"","Sí, pero está en "&O8&": hacer el traslado a Carepa","Sí"))))) -> Sí | T8: Inventario_Equipos_Carepa.xlsx · Carepa · fila 8
A9: EQP-CAR-0008 | B9: No | D9: ESTERIOSCOPIO | E9: OPTIKA | F9: SZM-2 | G9: 390843 | H9: 027807 | I9: 151919 | J9: 101 | L9: 1 | M9: Operativo | N9: Buena | P9: =IF(D9="","",IF(M9="Baja","No: dado de baja",IF(M9="Fuera de servicio","No: fuera de servicio",IF(M9="En mantenimiento","No: en mantenimiento",IF(O9<>"","Sí, pero está en "&O9&": hacer el traslado a Carepa","Sí"))))) -> Sí | T9: Inventario_Equipos_Carepa.xlsx · Carepa · fila 9
A10: EQP-CAR-0009 | B10: No | D10: ESTERIOSCOPIO | E10: OPTIKA | F10: SZM-2 | G10: 390838 | H10: 027808 | I10: 151920 | J10: 101 | L10: 1 | M10: Operativo | N10: Buena | P10: =IF(D10="","",IF(M10="Baja","No: dado de baja",IF(M10="Fuera de servicio","No: fuera de servicio",IF(M10="En mantenimiento","No: en mantenimiento",IF(O10<>"","Sí, pero está en "&O10&": hacer el traslado a Carepa","Sí"))))) -> Sí | T10: Inventario_Equipos_Carepa.xlsx · Carepa · fila 10
A11: EQP-CAR-0010 | B11: No | D11: ESTERIOSCOPIO | E11: OPTIKA | F11: SZM-2 | G11: 390837 | H11: 027810 | I11: 151922 | J11: 101 | L11: 1 | M11: Operativo | N11: Buena | P11: =IF(D11="","",IF(M11="Baja","No: dado de baja",IF(M11="Fuera de servicio","No: fuera de servicio",IF(M11="En mantenimiento","No: en mantenimiento",IF(O11<>"","Sí, pero está en "&O11&": hacer el traslado a Carepa","Sí"))))) -> Sí | T11: Inventario_Equipos_Carepa.xlsx · Carepa · fila 11
A12: EQP-CAR-0011 | B12: No | D12: ESTERIOSCOPIO | E12: OPTIKA | F12: SZM-2 | G12: 390844 | H12: 027811 | I12: 151923 | J12: 101 | L12: 1 | M12: Operativo | N12: Buena | P12: =IF(D12="","",IF(M12="Baja","No: dado de baja",IF(M12="Fuera de servicio","No: fuera de servicio",IF(M12="En mantenimiento","No: en mantenimiento",IF(O12<>"","Sí, pero está en "&O12&": hacer el traslado a Carepa","Sí"))))) -> Sí | T12: Inventario_Equipos_Carepa.xlsx · Carepa · fila 12
A13: EQP-CAR-0012 | B13: No | D13: ESTERIOSCOPIO | E13: OPTIKA | F13: SZM-2 | G13: 390845 | H13: 027812 | I13: 151924 | J13: 101 | L13: 1 | M13: Operativo | N13: Buena | P13: =IF(D13="","",IF(M13="Baja","No: dado de baja",IF(M13="Fuera de servicio","No: fuera de servicio",IF(M13="En mantenimiento","No: en mantenimiento",IF(O13<>"","Sí, pero está en "&O13&": hacer el traslado a Carepa","Sí"))))) -> Sí | T13: Inventario_Equipos_Carepa.xlsx · Carepa · fila 13
A14: EQP-CAR-0013 | B14: No | D14: ESTERIOSCOPIO | E14: OPTIKA | F14: SZM-2 | G14: 390840 | H14: 027813 | I14: 151925 | J14: 101 | L14: 1 | M14: Operativo | N14: Buena | P14: =IF(D14="","",IF(M14="Baja","No: dado de baja",IF(M14="Fuera de servicio","No: fuera de servicio",IF(M14="En mantenimiento","No: en mantenimiento",IF(O14<>"","Sí, pero está en "&O14&": hacer el traslado a Carepa","Sí"))))) -> Sí | T14: Inventario_Equipos_Carepa.xlsx · Carepa · fila 14
A15: EQP-CAR-0014 | B15: Sí | C15: Préstamo o envío a Medellín (Centro de Instrumentación): registrar el traslado | D15: MICROSCOPIO | E15: OPTIKA | F15: B-352PL | G15: 388881 | H15: 027780 | I15: 151856 | L15: 1 | M15: Fuera de servicio | N15: Mala | O15: Medellín (Centro de Instrumentación) | P15: =IF(D15="","",IF(M15="Baja","No: dado de baja",IF(M15="Fuera de servicio","No: fuera de servicio",IF(M15="En mantenimiento","No: en mantenimiento",IF(O15<>"","Sí, pero está en "&O15&": hacer el traslado a Carepa","Sí"))))) -> No: fuera de servicio | S15: Ubicación original: Enviado al CII | T15: Inventario_Equipos_Carepa.xlsx · Carepa · fila 15
A16: EQP-CAR-0015 | B16: No | D16: MICROSCOPIO | E16: OPTIKA | F16: B-352PL | G16: 388884 | H16: 027781 | I16: 151857 | J16: 101 | L16: 1 | M16: Operativo | N16: Regular | P16: =IF(D16="","",IF(M16="Baja","No: dado de baja",IF(M16="Fuera de servicio","No: fuera de servicio",IF(M16="En mantenimiento","No: en mantenimiento",IF(O16<>"","Sí, pero está en "&O16&": hacer el traslado a Carepa","Sí"))))) -> Sí | T16: Inventario_Equipos_Carepa.xlsx · Carepa · fila 16
A17: EQP-CAR-0016 | B17: No | D17: MICROSCOPIO | E17: OPTIKA | F17: B-352PL | G17: 388889 | H17: 027782 | I17: 151858 | J17: 101 | L17: 1 | M17: Operativo | N17: Regular | P17: =IF(D17="","",IF(M17="Baja","No: dado de baja",IF(M17="Fuera de servicio","No: fuera de servicio",IF(M17="En mantenimiento","No: en mantenimiento",IF(O17<>"","Sí, pero está en "&O17&": hacer el traslado a Carepa","Sí"))))) -> Sí | T17: Inventario_Equipos_Carepa.xlsx · Carepa · fila 17
A18: EQP-CAR-0017 | B18: Sí | C18: Préstamo o envío a Medellín (Centro de Instrumentación): registrar el traslado | D18: MICROSCOPIO | E18: OPTIKA | F18: B-352PL | G18: 388893 | H18: 027783 | I18: 151859 | L18: 1 | M18: Baja | N18: Regular | O18: Medellín (Centro de Instrumentación) | P18: =IF(D18="","",IF(M18="Baja","No: dado de baja",IF(M18="Fuera de servicio","No: fuera de servicio",IF(M18="En mantenimiento","No: en mantenimiento",IF(O18<>"","Sí, pero está en "&O18&": hacer el traslado a Carepa","Sí"))))) -> No: dado de baja | S18: DADO DE BAJA | Ubicación original: Enviado a Medellin | T18: Inventario_Equipos_Carepa.xlsx · Carepa · fila 18
A19: EQP-CAR-0018 | B19: Sí | C19: Préstamo o envío a Medellín (Centro de Instrumentación): registrar el traslado | D19: MICROSCOPIO | E19: OPTIKA | F19: B-352PL | G19: 388886 | H19: 027784 | I19: 151860 | L19: 1 | M19: Baja | N19: Mala | O19: Medellín (Centro de Instrumentación) | P19: =IF(D19="","",IF(M19="Baja","No: dado de baja",IF(M19="Fuera de servicio","No: fuera de servicio",IF(M19="En mantenimiento","No: en mantenimiento",IF(O19<>"","Sí, pero está en "&O19&": hacer el traslado a Carepa","Sí"))))) -> No: dado de baja | S19: DADO DE BAJA | Ubicación original: Enviado al CII | T19: Inventario_Equipos_Carepa.xlsx · Carepa · fila 19
A20: EQP-CAR-0019 | B20: No | D20: MICROSCOPIO | E20: OPTIKA | F20: B-352PL | G20: 388894 | H20: 027786 | I20: 151862 | J20: 101 | L20: 1 | M20: Operativo | N20: Regular | P20: =IF(D20="","",IF(M20="Baja","No: dado de baja",IF(M20="Fuera de servicio","No: fuera de servicio",IF(M20="En mantenimiento","No: en mantenimiento",IF(O20<>"","Sí, pero está en "&O20&": hacer el traslado a Carepa","Sí"))))) -> Sí | T20: Inventario_Equipos_Carepa.xlsx · Carepa · fila 20
A21: EQP-CAR-0020 | B21: Sí | C21: Préstamo o envío a Medellín (Centro de Instrumentación): registrar el traslado | D21: MICROSCOPIO | E21: OPTIKA | F21: B-352PL | G21: 388879 | H21: 027787 | I21: 151863 | L21: 1 | M21: Baja | N21: Mala | O21: Medellín (Centro de Instrumentación) | P21: =IF(D21="","",IF(M21="Baja","No: dado de baja",IF(M21="Fuera de servicio","No: fuera de servicio",IF(M21="En mantenimiento","No: en mantenimiento",IF(O21<>"","Sí, pero está en "&O21&": hacer el traslado a Carepa","Sí"))))) -> No: dado de baja | S21: DADO DE BAJA | Malo (ocular izquierdo malo) | Ubicación original: Enviado al CII | T21: Inventario_Equipos_Carepa.xlsx · Carepa · fila 21
A22: EQP-CAR-0021 | B22: Sí | C22: Préstamo o envío a Medellín (Centro de Instrumentación): registrar el traslado | D22: MICROSCOPIO | E22: OPTIKA | F22: B-352PL | G22: 388883 | H22: 027788 | I22: 151864 | L22: 1 | M22: Baja | N22: Regular | O22: Medellín (Centro de Instrumentación) | P22: =IF(D22="","",IF(M22="Baja","No: dado de baja",IF(M22="Fuera de servicio","No: fuera de servicio",IF(M22="En mantenimiento","No: en mantenimiento",IF(O22<>"","Sí, pero está en "&O22&": hacer el traslado a Carepa","Sí"))))) -> No: dado de baja | S22: DADO DE BAJA | Ubicación original: Enviado a Medellin | T22: Inventario_Equipos_Carepa.xlsx · Carepa · fila 22
A23: EQP-CAR-0022 | B23: No | D23: MICROSCOPIO | E23: OPTIKA | F23: B-352PL | G23: 388890 | H23: 027789 | I23: 151865 | J23: 101 | L23: 1 | M23: Operativo | N23: Regular | P23: =IF(D23="","",IF(M23="Baja","No: dado de baja",IF(M23="Fuera de servicio","No: fuera de servicio",IF(M23="En mantenimiento","No: en mantenimiento",IF(O23<>"","Sí, pero está en "&O23&": hacer el traslado a Carepa","Sí"))))) -> Sí | T23: Inventario_Equipos_Carepa.xlsx · Carepa · fila 23
A24: EQP-CAR-0023 | B24: Sí | C24: Préstamo o envío a Medellín (Centro de Instrumentación): registrar el traslado | D24: MICROSCOPIO | E24: OPTIKA | F24: B-352PL | G24: 388895 | H24: 027790 | I24: 151866 | L24: 1 | M24: Baja | N24: Mala | O24: Medellín (Centro de Instrumentación) | P24: =IF(D24="","",IF(M24="Baja","No: dado de baja",IF(M24="Fuera de servicio","No: fuera de servicio",IF(M24="En mantenimiento","No: en mantenimiento",IF(O24<>"","Sí, pero está en "&O24&": hacer el traslado a Carepa","Sí"))))) -> No: dado de baja | S24: DADO DE BAJA | Ubicación original: Enviado al CII | T24: Inventario_Equipos_Carepa.xlsx · Carepa · fila 24
A25: EQP-CAR-0024 | B25: No | D25: MICROSCOPIO | E25: OPTIKA | F25: B-352PL | G25: 388880 | H25: 027791 | I25: 151867 | J25: 101 | L25: 1 | M25: Operativo | N25: Regular | P25: =IF(D25="","",IF(M25="Baja","No: dado de baja",IF(M25="Fuera de servicio","No: fuera de servicio",IF(M25="En mantenimiento","No: en mantenimiento",IF(O25<>"","Sí, pero está en "&O25&": hacer el traslado a Carepa","Sí"))))) -> Sí | T25: Inventario_Equipos_Carepa.xlsx · Carepa · fila 25
A26: EQP-CAR-0025 | B26: Sí | C26: Pendiente de dar de baja; Préstamo o envío a Medellín (Centro de Instrumentación): registrar el traslado | D26: MICROSCOPIO | E26: OPTIKA | F26: B-352PL | G26: 388891 | H26: 027793 | I26: 151869 | L26: 1 | M26: Fuera de servicio | N26: Regular | O26: Medellín (Centro de Instrumentación) | P26: =IF(D26="","",IF(M26="Baja","No: dado de baja",IF(M26="Fuera de servicio","No: fuera de servicio",IF(M26="En mantenimiento","No: en mantenimiento",IF(O26<>"","Sí, pero está en "&O26&": hacer el traslado a Carepa","Sí"))))) -> No: fuera de servicio | S26: Dar de baja | Ubicación original: Enviado a Medellin | T26: Inventario_Equipos_Carepa.xlsx · Carepa · fila 26
A27: EQP-CAR-0026 | B27: No | D27: MICROSCOPIO | E27: OPTIKA | F27: B-352PL | G27: 388888 | H27: 027794 | I27: 151870 | J27: 101 | L27: 1 | M27: Operativo | N27: Regular | P27: =IF(D27="","",IF(M27="Baja","No: dado de baja",IF(M27="Fuera de servicio","No: fuera de servicio",IF(M27="En mantenimiento","No: en mantenimiento",IF(O27<>"","Sí, pero está en "&O27&": hacer el traslado a Carepa","Sí"))))) -> Sí | T27: Inventario_Equipos_Carepa.xlsx · Carepa · fila 27
A28: EQP-CAR-0027 | B28: No | D28: MICROSCOPIO | E28: OPTIKA | F28: B-352PL | G28: 388885 | H28: 027795 | I28: 151871 | J28: 101 | L28: 1 | M28: Operativo | N28: Regular | P28: =IF(D28="","",IF(M28="Baja","No: dado de baja",IF(M28="Fuera de servicio","No: fuera de servicio",IF(M28="En mantenimiento","No: en mantenimiento",IF(O28<>"","Sí, pero está en "&O28&": hacer el traslado a Carepa","Sí"))))) -> Sí | T28: Inventario_Equipos_Carepa.xlsx · Carepa · fila 28
A29: EQP-CAR-0028 | B29: No | D29: MICROSCOPIO | E29: OPTIKA | F29: B-352PL | G29: 388892 | H29: 027796 | I29: 151872 | J29: 101 | L29: 1 | M29: Operativo | N29: Regular | P29: =IF(D29="","",IF(M29="Baja","No: dado de baja",IF(M29="Fuera de servicio","No: fuera de servicio",IF(M29="En mantenimiento","No: en mantenimiento",IF(O29<>"","Sí, pero está en "&O29&": hacer el traslado a Carepa","Sí"))))) -> Sí | T29: Inventario_Equipos_Carepa.xlsx · Carepa · fila 29
A30: EQP-CAR-0029 | B30: No | D30: OLLA AUTOCLAVE | E30: WARNING | F30: 25X-1 | G30: D0030361 | H30: 027764 | I30: 158587 | J30: 101 | L30: 1 | M30: Operativo | N30: Buena | P30: =IF(D30="","",IF(M30="Baja","No: dado de baja",IF(M30="Fuera de servicio","No: fuera de servicio",IF(M30="En mantenimiento","No: en mantenimiento",IF(O30<>"","Sí, pero está en "&O30&": hacer el traslado a Carepa","Sí"))))) -> Sí | T30: Inventario_Equipos_Carepa.xlsx · Carepa · fila 30
A31: EQP-CAR-0030 | B31: No | D31: OLLA AUTOCLAVE | E31: WARNING | F31: 25X-1 | G31: D0030379 | H31: 027763 | I31: 158586 | J31: 103 | L31: 1 | M31: Operativo | N31: Buena | P31: =IF(D31="","",IF(M31="Baja","No: dado de baja",IF(M31="Fuera de servicio","No: fuera de servicio",IF(M31="En mantenimiento","No: en mantenimiento",IF(O31<>"","Sí, pero está en "&O31&": hacer el traslado a Carepa","Sí"))))) -> Sí | T31: Inventario_Equipos_Carepa.xlsx · Carepa · fila 31
A32: EQP-CAR-0031 | B32: No | D32: CABINA DE FLUJO LAMINAR | E32: GRUPO C4 | F32: MIN120 | G32: 362212 | I32: 204424 | J32: 101 | L32: 1 | M32: Operativo | N32: Buena | P32: =IF(D32="","",IF(M32="Baja","No: dado de baja",IF(M32="Fuera de servicio","No: fuera de servicio",IF(M32="En mantenimiento","No: en mantenimiento",IF(O32<>"","Sí, pero está en "&O32&": hacer el traslado a Carepa","Sí"))))) -> Sí | T32: Inventario_Equipos_Carepa.xlsx · Carepa · fila 32
A33: EQP-CAR-0032 | B33: No | D33: AUTOCLAVE | E33: PINGLOBAL | F33: 2021/Ref.JPA50LV | G33: 4588739 | I33: 189317 | J33: 101 | L33: 1 | M33: Operativo | N33: Buena | P33: =IF(D33="","",IF(M33="Baja","No: dado de baja",IF(M33="Fuera de servicio","No: fuera de servicio",IF(M33="En mantenimiento","No: en mantenimiento",IF(O33<>"","Sí, pero está en "&O33&": hacer el traslado a Carepa","Sí"))))) -> Sí | T33: Inventario_Equipos_Carepa.xlsx · Carepa · fila 33
A34: EQP-CAR-0033 | B34: No | D34: INCUBADORA | E34: BINDER | F34: ED-115 | G34: 13-16020 | H34: 027766 | I34: 151470 | J34: 101 | L34: 1 | M34: Operativo | N34: Buena | P34: =IF(D34="","",IF(M34="Baja","No: dado de baja",IF(M34="Fuera de servicio","No: fuera de servicio",IF(M34="En mantenimiento","No: en mantenimiento",IF(O34<>"","Sí, pero está en "&O34&": hacer el traslado a Carepa","Sí"))))) -> Sí | T34: Inventario_Equipos_Carepa.xlsx · Carepa · fila 34
A35: EQP-CAR-0034 | B35: No | D35: INCUBADORA | E35: BINDER | F35: ED-116 | G35: 13-16017 | H35: 036210 | I35: 152753 | J35: 101 | L35: 1 | M35: Operativo | N35: Buena | P35: =IF(D35="","",IF(M35="Baja","No: dado de baja",IF(M35="Fuera de servicio","No: fuera de servicio",IF(M35="En mantenimiento","No: en mantenimiento",IF(O35<>"","Sí, pero está en "&O35&": hacer el traslado a Carepa","Sí"))))) -> Sí | T35: Inventario_Equipos_Carepa.xlsx · Carepa · fila 35
A36: EQP-CAR-0035 | B36: No | D36: NEVERA DE 213L | E36: HACEB | F36: H6161FT22 | I36: 193005 | J36: 102 | L36: 1 | M36: Operativo | N36: Buena | P36: =IF(D36="","",IF(M36="Baja","No: dado de baja",IF(M36="Fuera de servicio","No: fuera de servicio",IF(M36="En mantenimiento","No: en mantenimiento",IF(O36<>"","Sí, pero está en "&O36&": hacer el traslado a Carepa","Sí"))))) -> Sí | T36: Inventario_Equipos_Carepa.xlsx · Carepa · fila 36
A37: EQP-CAR-0036 | B37: No | D37: NEVERA DE 213L | E37: HACEB | F37: H6161FT22 | I37: 193006 | J37: 103 | L37: 1 | M37: Operativo | N37: Buena | P37: =IF(D37="","",IF(M37="Baja","No: dado de baja",IF(M37="Fuera de servicio","No: fuera de servicio",IF(M37="En mantenimiento","No: en mantenimiento",IF(O37<>"","Sí, pero está en "&O37&": hacer el traslado a Carepa","Sí"))))) -> Sí | T37: Inventario_Equipos_Carepa.xlsx · Carepa · fila 37
A38: EQP-CAR-0037 | B38: No | D38: NEVERA de 420 litros | E38: Haceb | F38: NEV AS 420L SE 2P DA TI | G38: 90356431 | H38: 027893 | I38: 152752 | J38: 101 | L38: 1 | M38: Operativo | N38: Buena | P38: =IF(D38="","",IF(M38="Baja","No: dado de baja",IF(M38="Fuera de servicio","No: fuera de servicio",IF(M38="En mantenimiento","No: en mantenimiento",IF(O38<>"","Sí, pero está en "&O38&": hacer el traslado a Carepa","Sí"))))) -> Sí | T38: Inventario_Equipos_Carepa.xlsx · Carepa · fila 38
A39: EQP-CAR-0038 | B39: No | D39: ULTRACONGELADOR | E39: THERMO SCIENTIFIC | J39: 103 | L39: 1 | M39: Operativo | N39: Buena | P39: =IF(D39="","",IF(M39="Baja","No: dado de baja",IF(M39="Fuera de servicio","No: fuera de servicio",IF(M39="En mantenimiento","No: en mantenimiento",IF(O39<>"","Sí, pero está en "&O39&": hacer el traslado a Carepa","Sí"))))) -> Sí | T39: Inventario_Equipos_Carepa.xlsx · Carepa · fila 39
A40: EQP-CAR-0039 | B40: No | D40: REFRIGERADOR -20 | E40: INDUSFRIAL | G40: J15CDC3VN | H40: 027722 | I40: 162232 | J40: 103 | L40: 1 | M40: Fuera de servicio | N40: Mala | P40: =IF(D40="","",IF(M40="Baja","No: dado de baja",IF(M40="Fuera de servicio","No: fuera de servicio",IF(M40="En mantenimiento","No: en mantenimiento",IF(O40<>"","Sí, pero está en "&O40&": hacer el traslado a Carepa","Sí"))))) -> No: fuera de servicio | T40: Inventario_Equipos_Carepa.xlsx · Carepa · fila 40
...

Sheet Vidriería
A1: ID | B1: Revisar | C1: Ítem (p. ej. Beaker, Probeta, Pipeta aforada) | D1: Capacidad / especificación | E1: Material | F1: Cantidad buena | G1: Cantidad regular | H1: Cantidad dañada o dada de baja | I1: Rotas desde el conteo | J1: Útil hoy (buena + regular − rotas) | K1: Ubicación | L1: Fecha del conteo | M1: Observaciones
A2: VID-CAR-0001 | B2: No | I2: =IF(C2="","",SUMIFS(Roturas!$D$2:$D$2000,Roturas!$B$2:$B$2000,A2)) | J2: =IF(C2="","",N(F2)+N(G2)-I2)
A3: VID-CAR-0002 | B3: No | I3: =IF(C3="","",SUMIFS(Roturas!$D$2:$D$2000,Roturas!$B$2:$B$2000,A3)) | J3: =IF(C3="","",N(F3)+N(G3)-I3)
A4: VID-CAR-0003 | B4: No | I4: =IF(C4="","",SUMIFS(Roturas!$D$2:$D$2000,Roturas!$B$2:$B$2000,A4)) | J4: =IF(C4="","",N(F4)+N(G4)-I4)
A5: VID-CAR-0004 | B5: No | I5: =IF(C5="","",SUMIFS(Roturas!$D$2:$D$2000,Roturas!$B$2:$B$2000,A5)) | J5: =IF(C5="","",N(F5)+N(G5)-I5)
A6: VID-CAR-0005 | B6: No | I6: =IF(C6="","",SUMIFS(Roturas!$D$2:$D$2000,Roturas!$B$2:$B$2000,A6)) | J6: =IF(C6="","",N(F6)+N(G6)-I6)
A7: VID-CAR-0006 | B7: No | I7: =IF(C7="","",SUMIFS(Roturas!$D$2:$D$2000,Roturas!$B$2:$B$2000,A7)) | J7: =IF(C7="","",N(F7)+N(G7)-I7)
A8: VID-CAR-0007 | B8: No | I8: =IF(C8="","",SUMIFS(Roturas!$D$2:$D$2000,Roturas!$B$2:$B$2000,A8)) | J8: =IF(C8="","",N(F8)+N(G8)-I8)
A9: VID-CAR-0008 | B9: No | I9: =IF(C9="","",SUMIFS(Roturas!$D$2:$D$2000,Roturas!$B$2:$B$2000,A9)) | J9: =IF(C9="","",N(F9)+N(G9)-I9)
A10: VID-CAR-0009 | B10: No | I10: =IF(C10="","",SUMIFS(Roturas!$D$2:$D$2000,Roturas!$B$2:$B$2000,A10)) | J10: =IF(C10="","",N(F10)+N(G10)-I10)
A11: VID-CAR-0010 | B11: No | I11: =IF(C11="","",SUMIFS(Roturas!$D$2:$D$2000,Roturas!$B$2:$B$2000,A11)) | J11: =IF(C11="","",N(F11)+N(G11)-I11)
A12: VID-CAR-0011 | B12: No | I12: =IF(C12="","",SUMIFS(Roturas!$D$2:$D$2000,Roturas!$B$2:$B$2000,A12)) | J12: =IF(C12="","",N(F12)+N(G12)-I12)
A13: VID-CAR-0012 | B13: No | I13: =IF(C13="","",SUMIFS(Roturas!$D$2:$D$2000,Roturas!$B$2:$B$2000,A13)) | J13: =IF(C13="","",N(F13)+N(G13)-I13)
... A301: VID-CAR-0300 | B301: No | I301: =IF(C301="","",SUMIFS(Roturas!$D$2:$D$2000,Roturas!$B$2:$B$2000,A301)) | J301: =IF(C301="","",N(F301)+N(G301)-I301)

Sheet Roturas
A1: Fecha | B1: ID vidriería | C1: Ítem | D1: Cantidad rota o dada de baja | E1: Sesión / práctica | F1: Registró | G1: Observación
C2: =IF(B2="","",IFERROR(INDEX(Vidriería!$C$2:$C$301,MATCH(B2,Vidriería!$A$2:$A$301,0))&" "&INDEX(Vidriería!$D$2:$D$301,MATCH(B2,Vidriería!$A$2:$A$301,0)),"ID no existe"))
C3: =IF(B3="","",IFERROR(INDEX(Vidriería!$C$2:$C$301,MATCH(B3,Vidriería!$A$2:$A$301,0))&" "&INDEX(Vidriería!$D$2:$D$301,MATCH(B3,Vidriería!$A$2:$A$301,0)),"ID no existe"))
C4: =IF(B4="","",IFERROR(INDEX(Vidriería!$C$2:$C$301,MATCH(B4,Vidriería!$A$2:$A$301,0))&" "&INDEX(Vidriería!$D$2:$D$301,MATCH(B4,Vidriería!$A$2:$A$301,0)),"ID no existe"))
C5: =IF(B5="","",IFERROR(INDEX(Vidriería!$C$2:$C$301,MATCH(B5,Vidriería!$A$2:$A$301,0))&" "&INDEX(Vidriería!$D$2:$D$301,MATCH(B5,Vidriería!$A$2:$A$301,0)),"ID no existe"))
C6: =IF(B6="","",IFERROR(INDEX(Vidriería!$C$2:$C$301,MATCH(B6,Vidriería!$A$2:$A$301,0))&" "&INDEX(Vidriería!$D$2:$D$301,MATCH(B6,Vidriería!$A$2:$A$301,0)),"ID no existe"))
C7: =IF(B7="","",IFERROR(INDEX(Vidriería!$C$2:$C$301,MATCH(B7,Vidriería!$A$2:$A$301,0))&" "&INDEX(Vidriería!$D$2:$D$301,MATCH(B7,Vidriería!$A$2:$A$301,0)),"ID no existe"))
C8: =IF(B8="","",IFERROR(INDEX(Vidriería!$C$2:$C$301,MATCH(B8,Vidriería!$A$2:$A$301,0))&" "&INDEX(Vidriería!$D$2:$D$301,MATCH(B8,Vidriería!$A$2:$A$301,0)),"ID no existe"))
C9: =IF(B9="","",IFERROR(INDEX(Vidriería!$C$2:$C$301,MATCH(B9,Vidriería!$A$2:$A$301,0))&" "&INDEX(Vidriería!$D$2:$D$301,MATCH(B9,Vidriería!$A$2:$A$301,0)),"ID no existe"))
C10: =IF(B10="","",IFERROR(INDEX(Vidriería!$C$2:$C$301,MATCH(B10,Vidriería!$A$2:$A$301,0))&" "&INDEX(Vidriería!$D$2:$D$301,MATCH(B10,Vidriería!$A$2:$A$301,0)),"ID no existe"))
C11: =IF(B11="","",IFERROR(INDEX(Vidriería!$C$2:$C$301,MATCH(B11,Vidriería!$A$2:$A$301,0))&" "&INDEX(Vidriería!$D$2:$D$301,MATCH(B11,Vidriería!$A$2:$A$301,0)),"ID no existe"))
C12: =IF(B12="","",IFERROR(INDEX(Vidriería!$C$2:$C$301,MATCH(B12,Vidriería!$A$2:$A$301,0))&" "&INDEX(Vidriería!$D$2:$D$301,MATCH(B12,Vidriería!$A$2:$A$301,0)),"ID no existe"))
C13: =IF(B13="","",IFERROR(INDEX(Vidriería!$C$2:$C$301,MATCH(B13,Vidriería!$A$2:$A$301,0))&" "&INDEX(Vidriería!$D$2:$D$301,MATCH(B13,Vidriería!$A$2:$A$301,0)),"ID no existe"))
... C2001: =IF(B2001="","",IFERROR(INDEX(Vidriería!$C$2:$C$301,MATCH(B2001,Vidriería!$A$2:$A$301,0))&" "&INDEX(Vidriería!$D$2:$D$301,MATCH(B2001,Vidriería!$A$2:$A$301,0)),"ID no existe"))
